Workbook
Name NativeTimeline_Date: #N/A
Name Slicer_Date: #N/A
Name Slicer_Holiday: #N/A
Name Slicer_Hour: #N/A
Name Slicer_Temperature: #N/A
Name Slicer_Weathersit: #N/A
Name Slicer_Weekday: #N/A

Sheet DATASET 1
A1: No. | B1: Date | C1: Season | D1: Year | E1: Month | F1: Hour | G1: Holiday | H1: Weekday | I1: Weathersit | J1: Temp
A2: 1 | B2: 40544 | C2: 1 | D2: 0 | E2: 1 | F2: 0 | G2: FALSE | H2: 6 | I2: 1 | J2: 0.24 | M2: FOR TEMP
A3: 2 | B3: 40544 | C3: 1 | D3: 0 | E3: 1 | F3: 1 | G3: FALSE | H3: 6 | I3: 1 | J3: 0.22
A4: 3 | B4: 40544 | C4: 1 | D4: 0 | E4: 1 | F4: 2 | G4: FALSE | H4: 6 | I4: 1 | J4: 0.22 | M4: STATISTIC | N4: RESULT
A5: 4 | B5: 40544 | C5: 1 | D5: 0 | E5: 1 | F5: 3 | G5: FALSE | H5: 6 | I5: 1 | J5: 0.24
A6: 5 | B6: 40544 | C6: 1 | D6: 0 | E6: 1 | F6: 4 | G6: FALSE | H6: 6 | I6: 1 | J6: 0.24 | M6: Mean | N6: =AVERAGE(J2:J611) -> 0.19688525
A7: 6 | B7: 40544 | C7: 1 | D7: 0 | E7: 1 | F7: 5 | G7: FALSE | H7: 6 | I7: 2 | J7: 0.24 | M7: Median | N7: 0.2
A8: 7 | B8: 40544 | C8: 1 | D8: 0 | E8: 1 | F8: 6 | G8: FALSE | H8: 6 | I8: 1 | J8: 0.22 | M8: Standard Error | N8: =_xlfn.STDEV.S(dataset_1[Temp])/SQRT(COUNT(dataset_1[Temp])) -> 0.0032918965
A9: 8 | B9: 40544 | C9: 1 | D9: 0 | E9: 1 | F9: 7 | G9: FALSE | H9: 6 | I9: 1 | J9: 0.2 | M9: Mode | N9: =MODE(dataset_1[Temp]) -> 0.2
A10: 9 | B10: 40544 | C10: 1 | D10: 0 | E10: 1 | F10: 8 | G10: FALSE | H10: 6 | I10: 1 | J10: 0.24 | M10: Standard Deviation | N10: =_xlfn.STDEV.S(dataset_1[Temp]) -> 0.081303845
A11: 10 | B11: 40544 | C11: 1 | D11: 0 | E11: 1 | F11: 9 | G11: FALSE | H11: 6 | I11: 1 | J11: 0.32 | M11: Sample Variance | N11: =_xlfn.VAR.S(dataset_1[Temp]) -> 0.0066103152
A12: 11 | B12: 40544 | C12: 1 | D12: 0 | E12: 1 | F12: 10 | G12: FALSE | H12: 6 | I12: 1 | J12: 0.38 | M12: Minimum | N12: =MIN(dataset_1[Temp]) -> 0.02
A13: 12 | B13: 40544 | C13: 1 | D13: 0 | E13: 1 | F13: 11 | G13: FALSE | H13: 6 | I13: 1 | J13: 0.36 | M13: Maximum | N13: =MAX(dataset_1[Temp]) -> 0.46
A14: 13 | B14: 40544 | C14: 1 | D14: 0 | E14: 1 | F14: 12 | G14: FALSE | H14: 6 | I14: 1 | J14: 0.42 | M14: Sum | N14: =SUM(dataset_1[Temp]) -> 120.1
A15: 14 | B15: 40544 | C15: 1 | D15: 0 | E15: 1 | F15: 13 | G15: FALSE | H15: 6 | I15: 2 | J15: 0.46 | M15: Count | N15: =COUNT(dataset_1[Temp]) -> 610
A16: 15 | B16: 40544 | C16: 1 | D16: 0 | E16: 1 | F16: 14 | G16: FALSE | H16: 6 | I16: 2 | J16: 0.46
A17: 16 | B17: 40544 | C17: 1 | D17: 0 | E17: 1 | F17: 15 | G17: FALSE | H17: 6 | I17: 2 | J17: 0.44
A18: 17 | B18: 40544 | C18: 1 | D18: 0 | E18: 1 | F18: 16 | G18: FALSE | H18: 6 | I18: 2 | J18: 0.42
A19: 18 | B19: 40544 | C19: 1 | D19: 0 | E19: 1 | F19: 17 | G19: FALSE | H19: 6 | I19: 2 | J19: 0.44
A20: 19 | B20: 40544 | C20: 1 | D20: 0 | E20: 1 | F20: 18 | G20: FALSE | H20: 6 | I20: 3 | J20: 0.42
A21: 20 | B21: 40544 | C21: 1 | D21: 0 | E21: 1 | F21: 19 | G21: FALSE | H21: 6 | I21: 3 | J21: 0.42
A22: 21 | B22: 40544 | C22: 1 | D22: 0 | E22: 1 | F22: 20 | G22: FALSE | H22: 6 | I22: 2 | J22: 0.4
A23: 22 | B23: 40544 | C23: 1 | D23: 0 | E23: 1 | F23: 21 | G23: FALSE | H23: 6 | I23: 2 | J23: 0.4
A24: 23 | B24: 40544 | C24: 1 | D24: 0 | E24: 1 | F24: 22 | G24: FALSE | H24: 6 | I24: 2 | J24: 0.4
A25: 24 | B25: 40544 | C25: 1 | D25: 0 | E25: 1 | F25: 23 | G25: FALSE | H25: 6 | I25: 2 | J25: 0.46
A26: 25 | B26: 40545 | C26: 1 | D26: 0 | E26: 1 | F26: 0 | G26: FALSE | H26: 0 | I26: 2 | J26: 0.46
A27: 26 | B27: 40545 | C27: 1 | D27: 0 | E27: 1 | F27: 1 | G27: FALSE | H27: 0 | I27: 2 | J27: 0.44
... A611: 610 | B611: 40571 | C611: 1 | D611: 0 | E611: 1 | F611: 15 | G611: FALSE | H611: 5 | I611: 2 | J611: 0.2

Sheet DATASET 2
A1: No. | B1: ATemp | C1: Humidity | D1: Windspeed | E1: Casual | F1: Registered | G1: Count
A2: 1 | B2: 0.2879 | C2: 0.81 | D2: 0 | E2: 3 | F2: 13 | G2: 16 | L2: FOR HUMIDITY
A3: 2 | B3: 0.2727 | C3: 0.8 | D3: 0 | E3: 8 | F3: 32 | G3: 40
A4: 3 | B4: 0.2727 | C4: 0.8 | D4: 0 | E4: 5 | F4: 27 | G4: 32 | L4: STATISTIC | M4: RESULT
A5: 4 | B5: 0.2879 | C5: 0.75 | D5: 0 | E5: 3 | F5: 10 | G5: 13
A6: 5 | B6: 0.2879 | C6: 0.75 | D6: 0 | E6: 0 | F6: 1 | G6: 1 | L6: Mean | M6: =AVERAGE(dataset_2__2[Humidity]) -> 0.56247541
A7: 6 | B7: 0.2576 | C7: 0.75 | D7: 0.0896 | E7: 0 | F7: 1 | G7: 1 | L7: Median | M7: =MEDIAN(dataset_2__2[Humidity]) -> 0.52
A8: 7 | B8: 0.2727 | C8: 0.8 | D8: 0 | E8: 2 | F8: 0 | G8: 2 | L8: Standard Error | M8: =_xlfn.STDEV.S(dataset_1[Temp])/SQRT(COUNT(dataset_1[Temp])) -> 0.0032918965
A9: 8 | B9: 0.2576 | C9: 0.86 | D9: 0 | E9: 1 | F9: 2 | G9: 3 | L9: Mode | M9: =MODE(dataset_2__2[Humidity]) -> 0.47
A10: 9 | B10: 0 | C10: 0.75 | D10: 0 | E10: 1 | F10: 7 | G10: 8 | L10: Standard Deviation | M10: =_xlfn.STDEV.S(dataset_2__2[Humidity]) -> 0.17544016
A11: 10 | B11: 0.3485 | C11: 0.76 | D11: 0 | E11: 8 | F11: 6 | G11: 14 | L11: Sample Variance | M11: =_xlfn.VAR.S(dataset_2__2[Humidity]) -> 0.030779248
A12: 11 | B12: 0.3939 | C12: 0.76 | D12: 0.2537 | E12: 12 | F12: 24 | G12: 36 | L12: Minimum | M12: =MIN(dataset_2__2[Humidity]) -> 0.21
A13: 12 | B13: 0.3333 | C13: 0.81 | D13: 0.2836 | E13: 26 | F13: 30 | G13: 56 | L13: Maximum | M13: =MAX(dataset_2__2[Humidity]) -> 1
A14: 13 | B14: 0.4242 | C14: 0.77 | D14: 0.2836 | E14: 29 | F14: 55 | G14: 84 | L14: Sum | M14: =SUM(dataset_2__2[Humidity]) -> 343.11
A15: 14 | B15: 0.4545 | C15: 0.72 | D15: 0.2985 | E15: 47 | F15: 47 | G15: 94 | L15: Count | M15: =COUNT(dataset_2__2[Humidity]) -> 610
A16: 15 | B16: 0.4545 | C16: 0.72 | D16: 0.2836 | E16: 35 | F16: 71 | G16: 106
A17: 16 | B17: 0.4394 | C17: 0.77 | D17: 0.2985 | E17: 40 | F17: 70 | G17: 110
A18: 17 | B18: 0.4242 | C18: 0.82 | D18: 0.2985 | E18: 41 | F18: 52 | G18: 93
A19: 18 | B19: 0 | C19: 0.82 | D19: 0.2836 | E19: 15 | F19: 52 | G19: 67
A20: 19 | B20: 0.4242 | C20: 0.88 | D20: 0.2537 | E20: 9 | F20: 26 | G20: 35
A21: 20 | B21: 0.4242 | C21: 0.88 | D21: 0.2537 | E21: 6 | F21: 31 | G21: 37
A22: 21 | B22: 0.4091 | C22: 0.87 | D22: 0.2537 | E22: 11 | F22: 25 | G22: 36
A23: 22 | B23: 0.4091 | C23: 0.87 | D23: 0.194 | E23: 3 | F23: 31 | G23: 34
A24: 23 | B24: 0.4091 | C24: 0.94 | D24: 0.2239 | E24: 11 | F24: 17 | G24: 28
A25: 24 | B25: 0 | C25: 0.88 | D25: 0.2985 | E25: 15 | F25: 24 | G25: 39
A26: 25 | B26: 0.4545 | C26: 0.88 | D26: 0.2985 | E26: 4 | F26: 13 | G26: 17
A27: 26 | B27: 0.4394 | C27: 0.94 | D27: 0.2537 | E27: 1 | F27: 16 | G27: 17
... A611: 610 | B611: 0.2576 | C611: 0.86 | D611: 0 | E611: 1 | F611: 40 | G611: 41

Sheet DATASETA  1 + 2
A1: No. | B1: Date | C1: Hour | D1: Holiday | E1: Weekday | F1: Weathersit | G1: Temp | H1: ATemp | I1: Humidity | J1: Windspeed | K1: Casual | L1: Registered | M1: Count
A2: 1 | B2: 40544 | C2: 0 | D2: FALSE | E2: 6 | F2: 1 | G2: 0.24 | H2: 0.2879 | I2: 0.81 | J2: 0 | K2: 3 | L2: 13 | M2: 16
A3: 2 | B3: 40544 | C3: 1 | D3: FALSE | E3: 6 | F3: 1 | G3: 0.22 | H3: 0.2727 | I3: 0.8 | J3: 0 | K3: 8 | L3: 32 | M3: 40
A4: 3 | B4: 40544 | C4: 2 | D4: FALSE | E4: 6 | F4: 1 | G4: 0.22 | H4: 0.2727 | I4: 0.8 | J4: 0 | K4: 5 | L4: 27 | M4: 32
A5: 4 | B5: 40544 | C5: 3 | D5: FALSE | E5: 6 | F5: 1 | G5: 0.24 | H5: 0.2879 | I5: 0.75 | J5: 0 | K5: 3 | L5: 10 | M5: 13
A6: 5 | B6: 40544 | C6: 4 | D6: FALSE | E6: 6 | F6: 1 | G6: 0.24 | H6: 0.2879 | I6: 0.75 | J6: 0 | K6: 0 | L6: 1 | M6: 1
A7: 6 | B7: 40544 | C7: 5 | D7: FALSE | E7: 6 | F7: 2 | G7: 0.24 | H7: 0.2576 | I7: 0.75 | J7: 0.0896 | K7: 0 | L7: 1 | M7: 1
A8: 7 | B8: 40544 | C8: 6 | D8: FALSE | E8: 6 | F8: 1 | G8: 0.22 | H8: 0.2727 | I8: 0.8 | J8: 0 | K8: 2 | L8: 0 | M8: 2
A9: 8 | B9: 40544 | C9: 7 | D9: FALSE | E9: 6 | F9: 1 | G9: 0.2 | H9: 0.2576 | I9: 0.86 | J9: 0 | K9: 1 | L9: 2 | M9: 3
A10: 9 | B10: 40544 | C10: 8 | D10: FALSE | E10: 6 | F10: 1 | G10: 0.24 | H10: 0 | I10: 0.75 | J10: 0 | K10: 1 | L10: 7 | M10: 8
A11: 10 | B11: 40544 | C11: 9 | D11: FALSE | E11: 6 | F11: 1 | G11: 0.32 | H11: 0.3485 | I11: 0.76 | J11: 0 | K11: 8 | L11: 6 | M11: 14
A12: 11 | B12: 40544 | C12: 10 | D12: FALSE | E12: 6 | F12: 1 | G12: 0.38 | H12: 0.3939 | I12: 0.76 | J12: 0.2537 | K12: 12 | L12: 24 | M12: 36
A13: 12 | B13: 40544 | C13: 11 | D13: FALSE | E13: 6 | F13: 1 | G13: 0.36 | H13: 0.3333 | I13: 0.81 | J13: 0.2836 | K13: 26 | L13: 30 | M13: 56
... A611: 610 | B611: 40571 | C611: 15 | D611: FALSE | E611: 5 | F611: 2 | G611: 0.2 | H611: 0.2576 | I611: 0.86 | J611: 0 | K611: 1 | L611: 40 | M611: 41

Sheet DATASET 3
A1: No. | B1: Date | C1: Season | D1: Year | E1: Month | F1: Hour | G1: Holiday | H1: Weekday | I1: Weathersit | J1: Temp | K1: ATemp | L1: Humidity | M1: Windspeed | N1: Casual | O1: Registered | P1: Count
A2: 620 | B2: 40572 | C2: 1 | D2: 0 | E2: 1 | F2: 1 | G2: FALSE | H2: 6 | I2: 1 | J2: 0.22 | K2: 0.2273 | L2: 0.64 | M2: 0.194 | N2: 0 | O2: 20 | P2: 20 | T2: FOR ATEMP
A3: 621 | B3: 40572 | C3: 1 | D3: 0 | E3: 1 | F3: 2 | G3: FALSE | H3: 6 | I3: 1 | J3: 0.22 | K3: 0.2273 | L3: 0.64 | M3: 0.1642 | N3: 0 | O3: 15 | P3: 15
A4: 622 | B4: 40572 | C4: 1 | D4: 0 | E4: 1 | F4: 3 | G4: FALSE | H4: 6 | I4: 1 | J4: 0.2 | K4: 0.2121 | L4: 0.64 | M4: 0.1343 | N4: 3 | O4: 5 | P4: 8
A5: 623 | B5: 40572 | C5: 1 | D5: 0 | E5: 1 | F5: 4 | G5: FALSE | H5: 6 | I5: 1 | J5: 0.16 | K5: 0.1818 | L5: 0.69 | M5: 0.1045 | N5: 1 | O5: 2 | P5: 3 | T5: STATISTIC | U5: RESULT
A6: 624 | B6: 40572 | C6: 1 | D6: 0 | E6: 1 | F6: 6 | G6: FALSE | H6: 6 | I6: 1 | J6: 0.16 | K6: 0.1818 | L6: 0.64 | M6: 0.1343 | N6: 0 | O6: 2 | P6: 2
A7: 625 | B7: 40572 | C7: 1 | D7: 0 | E7: 1 | F7: 7 | G7: FALSE | H7: 6 | I7: 1 | J7: 0.16 | K7: 0.1818 | L7: 0.59 | M7: 0.1045 | N7: 1 | O7: 4 | P7: 5 | T7: Mean | U7: =AVERAGE(dataset_3[ATemp]) -> 0.23042385
A8: 626 | B8: 40572 | C8: 1 | D8: 0 | E8: 1 | F8: 8 | G8: FALSE | H8: 6 | I8: 1 | J8: 0.18 | K8: 0.197 | L8: 0.55 | M8: 0.1642 | N8: 3 | O8: 31 | P8: 34 | T8: Median | U8: =MEDIAN(dataset_3[ATemp]) -> 0.2273
A9: 627 | B9: 40572 | C9: 1 | D9: 0 | E9: 1 | F9: 9 | G9: FALSE | H9: 6 | I9: 1 | J9: 0.18 | K9: 0.2121 | L9: 0.59 | M9: 0.0896 | N9: 0 | O9: 34 | P9: 34 | T9: Standard Error | U9: =_xlfn.STDEV.S(dataset_1[Temp])/SQRT(COUNT(dataset_1[Temp])) -> 0.0032918965
A10: 628 | B10: 40572 | C10: 1 | D10: 0 | E10: 1 | F10: 10 | G10: FALSE | H10: 6 | I10: 2 | J10: 0.18 | K10: 0.2121 | L10: 0.64 | M10: 0.1045 | N10: 4 | O10: 51 | P10: 55 | T10: Mode | U10: =MODE(dataset_3[ATemp]) -> 0.2273
A11: 629 | B11: 40572 | C11: 1 | D11: 0 | E11: 1 | F11: 11 | G11: FALSE | H11: 6 | I11: 2 | J11: 0.18 | K11: 0.197 | L11: 0.64 | M11: 0.1343 | N11: 4 | O11: 60 | P11: 64 | T11: Standard Deviation | U11: =_xlfn.STDEV.S(dataset_3[ATemp]) -> 0.069455389
A12: 630 | B12: 40572 | C12: 1 | D12: 0 | E12: 1 | F12: 12 | G12: FALSE | H12: 6 | I12: 2 | J12: 0.2 | K12: 0.197 | L12: 0.59 | M12: 0.194 | N12: 12 | O12: 66 | P12: 78 | T12: Sample Variance | U12: =_xlfn.VAR.S(dataset_3[ATemp]) -> 0.004824051
A13: 631 | B13: 40572 | C13: 1 | D13: 0 | E13: 1 | F13: 13 | G13: FALSE | H13: 6 | I13: 2 | J13: 0.22 | K13: 0.2273 | L13: 0.55 | M13: 0.1642 | N13: 9 | O13: 56 | P13: 65 | T13: Minimum | U13: =MIN(dataset_3[ATemp]) -> 0.0758
A14: 632 | B14: 40572 | C14: 1 | D14: 0 | E14: 1 | F14: 14 | G14: FALSE | H14: 6 | I14: 2 | J14: 0.22 | K14: 0.2273 | L14: 0.6 | M14: 0.1343 | N14: 10 | O14: 89 | P14: 99 | T14: Maximum | U14: =MAX(dataset_3[ATemp]) -> 0.4242
A15: 633 | B15: 40572 | C15: 1 | D15: 0 | E15: 1 | F15: 15 | G15: FALSE | H15: 6 | I15: 1 | J15: 0.22 | K15: 0.2121 | L15: 0.69 | M15: 0.2537 | N15: 22 | O15: 98 | P15: 120 | T15: Sum | U15: =SUM(dataset_3[ATemp]) -> 89.8653
A16: 634 | B16: 40572 | C16: 1 | D16: 0 | E16: 1 | F16: 16 | G16: FALSE | H16: 6 | I16: 1 | J16: 0.24 | K16: 0.2424 | L16: 0.6 | M16: 0.1642 | N16: 19 | O16: 88 | P16: 107 | T16: Count | U16: =COUNT(dataset_3[ATemp]) -> 390
A17: 635 | B17: 40572 | C17: 1 | D17: 0 | E17: 1 | F17: 17 | G17: FALSE | H17: 6 | I17: 1 | J17: 0.24 | K17: 0.2879 | L17: 0.6 | M17: 0 | N17: 9 | O17: 82 | P17: 91
A18: 636 | B18: 40572 | C18: 1 | D18: 0 | E18: 1 | F18: 18 | G18: FALSE | H18: 6 | I18: 1 | J18: 0.22 | K18: 0.2273 | L18: 0.69 | M18: 0.1343 | N18: 9 | O18: 59 | P18: 68
A19: 637 | B19: 40572 | C19: 1 | D19: 0 | E19: 1 | F19: 19 | G19: FALSE | H19: 6 | I19: 2 | J19: 0.22 | K19: 0.2121 | L19: 0.69 | M19: 0.2537 | N19: 6 | O19: 52 | P19: 58 | T19: FOR WINDSPEED
A20: 638 | B20: 40572 | C20: 1 | D20: 0 | E20: 1 | F20: 20 | G20: FALSE | H20: 6 | I20: 1 | J20: 0.18 | K20: 0.2121 | L20: 0.74 | M20: 0.0896 | N20: 1 | O20: 42 | P20: 43
A21: 639 | B21: 40572 | C21: 1 | D21: 0 | E21: 1 | F21: 21 | G21: FALSE | H21: 6 | I21: 1 | J21: 0.18 | K21: 0.2121 | L21: 0.74 | M21: 0.0896 | N21: 1 | O21: 35 | P21: 36 | T21: STATISTIC | U21: RESULT
A22: 640 | B22: 40572 | C22: 1 | D22: 0 | E22: 1 | F22: 22 | G22: FALSE | H22: 6 | I22: 1 | J22: 0.16 | K22: 0.197 | L22: 0.8 | M22: 0.0896 | N22: 4 | O22: 28 | P22: 32
A23: 641 | B23: 40572 | C23: 1 | D23: 0 | E23: 1 | F23: 23 | G23: FALSE | H23: 6 | I23: 1 | J23: 0.16 | K23: 0.197 | L23: 0.8 | M23: 0.0896 | N23: 3 | O23: 30 | P23: 33 | T23: Mean | U23: =AVERAGE(dataset_3[Windspeed]) -> 0.1794159
A24: 642 | B24: 40573 | C24: 1 | D24: 0 | E24: 1 | F24: 0 | G24: FALSE | H24: 0 | I24: 1 | J24: 0.16 | K24: 0.1818 | L24: 0.8 | M24: 0.1045 | N24: 0 | O24: 33 | P24: 33 | T24: Median | U24: =MEDIAN(dataset_3[Windspeed]) -> 0.1642
A25: 643 | B25: 40573 | C25: 1 | D25: 0 | E25: 1 | F25: 1 | G25: FALSE | H25: 0 | I25: 1 | J25: 0.14 | K25: 0.2121 | L25: 0.8 | M25: 0 | N25: 7 | O25: 22 | P25: 29 | T25: Standard Error | U25: =_xlfn.STDEV.S(M3/SQRT(COUNT(M2))) -> #DIV/0!
A26: 644 | B26: 40573 | C26: 1 | D26: 0 | E26: 1 | F26: 2 | G26: FALSE | H26: 0 | I26: 1 | J26: 0.16 | K26: 0.2273 | L26: 0.8 | M26: 0 | N26: 1 | O26: 10 | P26: 11 | T26: Mode | U26: =MODE(dataset_3[Windspeed]) -> 0
A27: 645 | B27: 40573 | C27: 1 | D27: 0 | E27: 1 | F27: 3 | G27: FALSE | H27: 0 | I27: 1 | J27: 0.14 | K27: 0.2121 | L27: 0.93 | M27: 0 | N27: 1 | O27: 7 | P27: 8 | T27: Standard Deviation | U27: =_xlfn.STDEV.S(#REF!) -> #REF!
A28: 646 | B28: 40573 | C28: 1 | D28: 0 | E28: 1 | F28: 4 | G28: FALSE | H28: 0 | I28: 1 | J28: 0.14 | K28: 0.2121 | L28: 0.93 | M28: 0 | N28: 0 | O28: 1 | P28: 1 | T28: Sample Variance | U28: =_xlfn.VAR.S(dataset_3[Windspeed]) -> 0.019196457
A29: 647 | B29: 40573 | C29: 1 | D29: 0 | E29: 1 | F29: 5 | G29: FALSE | H29: 0 | I29: 1 | J29: 0.14 | K29: 0.2121 | L29: 0.86 | M29: 0 | N29: 0 | O29: 3 | P29: 3 | T29: Minimum | U29: =MIN(dataset_3[Windspeed]) -> 0
A30: 648 | B30: 40573 | C30: 1 | D30: 0 | E30: 1 | F30: 7 | G30: FALSE | H30: 0 | I30: 1 | J30: 0.14 | K30: 0.2121 | L30: 0.86 | M30: 0 | N30: 0 | O30: 3 | P30: 3 | T30: Maximum | U30: =MAX(dataset_3[Windspeed]) -> 0.5821
A31: 649 | B31: 40573 | C31: 1 | D31: 0 | E31: 1 | F31: 8 | G31: FALSE | H31: 0 | I31: 2 | J31: 0.14 | K31: 0.2121 | L31: 0.86 | M31: 0 | N31: 1 | O31: 11 | P31: 12 | T31: Sum | U31: =SUM(#REF!) -> #REF!
A32: 650 | B32: 40573 | C32: 1 | D32: 0 | E32: 1 | F32: 9 | G32: FALSE | H32: 0 | I32: 2 | J32: 0.16 | K32: 0.2273 | L32: 0.8 | M32: 0 | N32: 4 | O32: 34 | P32: 38 | T32: Count | U32: =COUNT(dataset_3[Windspeed]) -> 390
A33: 651 | B33: 40573 | C33: 1 | D33: 0 | E33: 1 | F33: 10 | G33: FALSE | H33: 0 | I33: 2 | J33: 0.18 | K33: 0.2424 | L33: 0.8 | M33: 0 | N33: 7 | O33: 57 | P33: 64
A34: 652 | B34: 40573 | C34: 1 | D34: 0 | E34: 1 | F34: 11 | G34: FALSE | H34: 0 | I34: 1 | J34: 0.22 | K34: 0.2727 | L34: 0.75 | M34: 0 | N34: 9 | O34: 50 | P34: 59
A35: 653 | B35: 40573 | C35: 1 | D35: 0 | E35: 1 | F35: 12 | G35: FALSE | H35: 0 | I35: 1 | J35: 0.3 | K35: 0.3182 | L35: 0.52 | M35: 0.1045 | N35: 10 | O35: 87 | P35: 97
A36: 654 | B36: 40573 | C36: 1 | D36: 0 | E36: 1 | F36: 13 | G36: FALSE | H36: 0 | I36: 1 | J36: 0.28 | K36: 0.2879 | L36: 0.61 | M36: 0.1045 | N36: 13 | O36: 71 | P36: 84
A37: 655 | B37: 40573 | C37: 1 | D37: 0 | E37: 1 | F37: 14 | G37: FALSE | H37: 0 | I37: 1 | J37: 0.28 | K37: 0.303 | L37: 0.61 | M37: 0.0896 | N37: 18 | O37: 104 | P37: 122
A38: 656 | B38: 40573 | C38: 1 | D38: 0 | E38: 1 | F38: 15 | G38: FALSE | H38: 0 | I38: 1 | J38: 0.3 | K38: 0.3333 | L38: 0.56 | M38: 0 | N38: 14 | O38: 95 | P38: 109
A39: 657 | B39: 40573 | C39: 1 | D39: 0 | E39: 1 | F39: 16 | G39: FALSE | H39: 0 | I39: 1 | J39: 0.3 | K39: 0.3333 | L39: 0.56 | M39: 0 | N39: 19 | O39: 104 | P39: 123
A40: 658 | B40: 40573 | C40: 1 | D40: 0 | E40: 1 | F40: 17 | G40: FALSE | H40: 0 | I40: 1 | J40: 0.3 | K40: 0.2879 | L40: 0.56 | M40: 0.194 | N40: 6 | O40: 71 | P40: 77
...

Sheet FINAL RESULT
A1: No. | B1: Date | C1: Hour | D1: Holiday | E1: Weekday | F1: Weathersit | G1: Temperature | H1: Assumed_temp | I1: humidity | J1: Windspeed | K1: Casual | L1: Registered | M1: Count
A2: 1 | B2: 40544 | C2: 0 | D2: FALSE | E2: =IF(WEEKDAY(B2,2)>=6,"Weekend","Weekday") -> Weekend | F2: 1 | G2: 0.24 | H2: 0.2879 | I2: 0.81 | J2: 0 | K2: 3 | L2: 13 | M2: 16 | P2: Dataset Overview
A3: 2 | B3: 40544 | C3: 1 | D3: FALSE | E3: =IF(WEEKDAY(B3,2)>=6,"Weekend","Weekday") -> Weekend | F3: 1 | G3: 0.22 | H3: 0.2727 | I3: 0.8 | J3: 0 | K3: 8 | L3: 32 | M3: 40
A4: 3 | B4: 40544 | C4: 2 | D4: FALSE | E4: =IF(WEEKDAY(B4,2)>=6,"Weekend","Weekday") -> Weekend | F4: 1 | G4: 0.22 | H4: 0.2727 | I4: 0.8 | J4: 0 | K4: 5 | L4: 27 | M4: 32
A5: 4 | B5: 40544 | C5: 3 | D5: FALSE | E5: =IF(WEEKDAY(B5,2)>=6,"Weekend","Weekday") -> Weekend | F5: 1 | G5: 0.24 | H5: 0.2879 | I5: 0.75 | J5: 0 | K5: 3 | L5: 10 | M5: 13 | O5: TOTAL | P5: RESULT | R5: Function | S5: Purpose | T5: Formula
A6: 5 | B6: 40544 | C6: 4 | D6: FALSE | E6: =IF(WEEKDAY(B6,2)>=6,"Weekend","Weekday") -> Weekend | F6: 1 | G6: 0.24 | H6: 0.2879 | I6: 0.75 | J6: 0 | K6: 0 | L6: 1 | M6: 1 | O6: Total of Casual Customer | P6: =SUM(Table5[Casual]) -> 4921 | R6: COUNTIF | S6: Counts the number of customers with demand greater than 100 | T6: =COUNTIF(Table5[Count],">100") -> 170
A7: 6 | B7: 40544 | C7: 5 | D7: FALSE | E7: =IF(WEEKDAY(B7,2)>=6,"Weekend","Weekday") -> Weekend | F7: 2 | G7: 0.24 | H7: 0.2576 | I7: 0.75 | J7: 0.0896 | K7: 0 | L7: 1 | M7: 1 | O7: Total of Registered Customer | P7: =SUM(Table5[Registered]) -> 53383 | R7: SUMIF | S7: Calculates the total demand where Count is greater than 100 | T7: =SUMIF(M2:M1001,">100",M2:M1001) -> 25164
A8: 7 | B8: 40544 | C8: 6 | D8: FALSE | E8: =IF(WEEKDAY(B8,2)>=6,"Weekend","Weekday") -> Weekend | F8: 1 | G8: 0.22 | H8: 0.2727 | I8: 0.8 | J8: 0 | K8: 2 | L8: 0 | M8: 2 | O8: Total Count of Customers | P8: =SUM(Table5[Count]) -> 58304 | R8: STDEV | S8: Calculates the standard deviation of total customer count | T8: =_xlfn.STDEV.S(M2:M1001) -> 50.985558
A9: 8 | B9: 40544 | C9: 7 | D9: FALSE | E9: =IF(WEEKDAY(B9,2)>=6,"Weekend","Weekday") -> Weekend | F9: 1 | G9: 0.2 | H9: 0.2576 | I9: 0.86 | J9: 0 | K9: 1 | L9: 2 | M9: 3 | R9: CORREL | S9: Measures the correlation between Casual and Registered cust | T9: =CORREL(K2:K1001,L2:L1001) -> 0.33770561
A10: 9 | B10: 40544 | C10: 8 | D10: FALSE | E10: =IF(WEEKDAY(B10,2)>=6,"Weekend","Weekday") -> Weekend | F10: 1 | G10: 0.24 | H10: 0 | I10: 0.75 | J10: 0 | K10: 1 | L10: 7 | M10: 8
A11: 10 | B11: 40544 | C11: 9 | D11: FALSE | E11: =IF(WEEKDAY(B11,2)>=6,"Weekend","Weekday") -> Weekend | F11: 1 | G11: 0.32 | H11: 0.3485 | I11: 0.76 | J11: 0 | K11: 8 | L11: 6 | M11: 14 | O11: AVERAGE | P11: RESULT
A12: 11 | B12: 40544 | C12: 10 | D12: FALSE | E12: =IF(WEEKDAY(B12,2)>=6,"Weekend","Weekday") -> Weekend | F12: 1 | G12: 0.38 | H12: 0.3939 | I12: 0.76 | J12: 0.2537 | K12: 12 | L12: 24 | M12: 36 | O12: Avg. Casual Customer | P12: =AVERAGE(Table5[Casual]) -> 4.921
A13: 12 | B13: 40544 | C13: 11 | D13: FALSE | E13: =IF(WEEKDAY(B13,2)>=6,"Weekend","Weekday") -> Weekend | F13: 1 | G13: 0.36 | H13: 0.3333 | I13: 0.81 | J13: 0.2836 | K13: 26 | L13: 30 | M13: 56 | O13: Avg. Registered Customer | P13: =AVERAGE(Table5[Registered]) -> 53.383
A14: 13 | B14: 40544 | C14: 12 | D14: FALSE | E14: =IF(WEEKDAY(B14,2)>=6,"Weekend","Weekday") -> Weekend | F14: 1 | G14: 0.42 | H14: 0.4242 | I14: 0.77 | J14: 0.2836 | K14: 29 | L14: 55 | M14: 84 | O14: Avg. Count Customer | P14: =AVERAGE(Table5[Count]) -> 58.304
A15: 14 | B15: 40544 | C15: 13 | D15: FALSE | E15: =IF(WEEKDAY(B15,2)>=6,"Weekend","Weekday") -> Weekend | F15: 2 | G15: 0.46 | H15: 0.4545 | I15: 0.72 | J15: 0.2985 | K15: 47 | L15: 47 | M15: 94
A16: 15 | B16: 40544 | C16: 14 | D16: FALSE | E16: =IF(WEEKDAY(B16,2)>=6,"Weekend","Weekday") -> Weekend | F16: 2 | G16: 0.46 | H16: 0.4545 | I16: 0.72 | J16: 0.2836 | K16: 35 | L16: 71 | M16: 106
A17: 16 | B17: 40544 | C17: 15 | D17: FALSE | E17: =IF(WEEKDAY(B17,2)>=6,"Weekend","Weekday") -> Weekend | F17: 2 | G17: 0.44 | H17: 0.4394 | I17: 0.77 | J17: 0.2985 | K17: 40 | L17: 70 | M17: 110 | O17: MAXIMUM | P17: RESULT
A18: 17 | B18: 40544 | C18: 16 | D18: FALSE | E18: =IF(WEEKDAY(B18,2)>=6,"Weekend","Weekday") -> Weekend | F18: 2 | G18: 0.42 | H18: 0.4242 | I18: 0.82 | J18: 0.2985 | K18: 41 | L18: 52 | M18: 93 | O18: Max of Casual Customer | P18: =MAX(Table5[Casual]) -> 62
A19: 18 | B19: 40544 | C19: 17 | D19: FALSE | E19: =IF(WEEKDAY(B19,2)>=6,"Weekend","Weekday") -> Weekend | F19: 2 | G19: 0.44 | H19: 0 | I19: 0.82 | J19: 0.2836 | K19: 15 | L19: 52 | M19: 67 | O19: Max of Registered Customer | P19: =MAX(Table5[Registered]) -> 247
A20: 19 | B20: 40544 | C20: 18 | D20: FALSE | E20: =IF(WEEKDAY(B20,2)>=6,"Weekend","Weekday") -> Weekend | F20: 3 | G20: 0.42 | H20: 0.4242 | I20: 0.88 | J20: 0.2537 | K20: 9 | L20: 26 | M20: 35 | O20: Max of Count Customer | P20: =MAX(Table5[Count]) -> 249
A21: 20 | B21: 40544 | C21: 19 | D21: FALSE | E21: =IF(WEEKDAY(B21,2)>=6,"Weekend","Weekday") -> Weekend | F21: 3 | G21: 0.42 | H21: 0.4242 | I21: 0.88 | J21: 0.2537 | K21: 6 | L21: 31 | M21: 37
A22: 21 | B22: 40544 | C22: 20 | D22: FALSE | E22: =IF(WEEKDAY(B22,2)>=6,"Weekend","Weekday") -> Weekend | F22: 2 | G22: 0.4 | H22: 0.4091 | I22: 0.87 | J22: 0.2537 | K22: 11 | L22: 25 | M22: 36
A23: 22 | B23: 40544 | C23: 21 | D23: FALSE | E23: =IF(WEEKDAY(B23,2)>=6,"Weekend","Weekday") -> Weekend | F23: 2 | G23: 0.4 | H23: 0.4091 | I23: 0.87 | J23: 0.194 | K23: 3 | L23: 31 | M23: 34 | O23: MINIMUM | P23: RESULT
A24: 23 | B24: 40544 | C24: 22 | D24: FALSE | E24: =IF(WEEKDAY(B24,2)>=6,"Weekend","Weekday") -> Weekend | F24: 2 | G24: 0.4 | H24: 0.4091 | I24: 0.94 | J24: 0.2239 | K24: 11 | L24: 17 | M24: 28 | O24: Min of Casual Customer | P24: =MIN(Table5[Casual]) -> 0
A25: 24 | B25: 40544 | C25: 23 | D25: FALSE | E25: =IF(WEEKDAY(B25,2)>=6,"Weekend","Weekday") -> Weekend | F25: 2 | G25: 0.46 | H25: 0 | I25: 0.88 | J25: 0.2985 | K25: 15 | L25: 24 | M25: 39 | O25: Min of Registered Customer | P25: =MIN(Table5[Registered]) -> 0
A26: 25 | B26: 40545 | C26: 0 | D26: FALSE | E26: =IF(WEEKDAY(B26,2)>=6,"Weekend","Weekday") -> Weekend | F26: 2 | G26: 0.46 | H26: 0.4545 | I26: 0.88 | J26: 0.2985 | K26: 4 | L26: 13 | M26: 17 | O26: Min of Count Customer | P26: =MIN(Table5[Count]) -> 1
A27: 26 | B27: 40545 | C27: 1 | D27: FALSE | E27: =IF(WEEKDAY(B27,2)>=6,"Weekend","Weekday") -> Weekend | F27: 2 | G27: 0.44 | H27: 0.4394 | I27: 0.94 | J27: 0.2537 | K27: 1 | L27: 16 | M27: 17
A28: 27 | B28: 40545 | C28: 2 | D28: FALSE | E28: =IF(WEEKDAY(B28,2)>=6,"Weekend","Weekday") -> Weekend | F28: 2 | G28: 0.42 | H28: 0.4242 | I28: 1 | J28: 0.2836 | K28: 1 | L28: 8 | M28: 9
A29: 28 | B29: 40545 | C29: 3 | D29: FALSE | E29: =IF(WEEKDAY(B29,2)>=6,"Weekend","Weekday") -> Weekend | F29: 2 | G29: 0.46 | H29: 0.4545 | I29: 0.94 | J29: 0.194 | K29: 2 | L29: 4 | M29: 6
A30: 29 | B30: 40545 | C30: 4 | D30: FALSE | E30: =IF(WEEKDAY(B30,2)>=6,"Weekend","Weekday") -> Weekend | F30: 2 | G30: 0.46 | H30: 0 | I30: 0.94 | J30: 0.194 | K30: 2 | L30: 1 | M30: 3
A31: 30 | B31: 40545 | C31: 6 | D31: FALSE | E31: =IF(WEEKDAY(B31,2)>=6,"Weekend","Weekday") -> Weekend | F31: 3 | G31: 0.42 | H31: 0.4242 | I31: 0.77 | J31: 0.2985 | K31: 0 | L31: 2 | M31: 2
A32: 31 | B32: 40545 | C32: 7 | D32: FALSE | E32: =IF(WEEKDAY(B32,2)>=6,"Weekend","Weekday") -> Weekend | F32: 2 | G32: 0.4 | H32: 0.4091 | I32: 0.76 | J32: 0.194 | K32: 0 | L32: 1 | M32: 1
A33: 32 | B33: 40545 | C33: 8 | D33: FALSE | E33: =IF(WEEKDAY(B33,2)>=6,"Weekend","Weekday") -> Weekend | F33: 3 | G33: 0.4 | H33: 0.4091 | I33: 0.71 | J33: 0.2239 | K33: 0 | L33: 8 | M33: 8
A34: 33 | B34: 40545 | C34: 9 | D34: FALSE | E34: =IF(WEEKDAY(B34,2)>=6,"Weekend","Weekday") -> Weekend | F34: 2 | G34: 0.38 | H34: 0 | I34: 0.76 | J34: 0.2239 | K34: 1 | L34: 19 | M34: 20
A35: 34 | B35: 40545 | C35: 10 | D35: FALSE | E35: =IF(WEEKDAY(B35,2)>=6,"Weekend","Weekday") -> Weekend | F35: 2 | G35: 0.36 | H35: 0.3485 | I35: 0.81 | J35: 0.2239 | K35: 7 | L35: 46 | M35: 53
A36: 35 | B36: 40545 | C36: 11 | D36: FALSE | E36: =IF(WEEKDAY(B36,2)>=6,"Weekend","Weekday") -> Weekend | F36: 2 | G36: 0.36 | H36: 0.3333 | I36: 0.71 | J36: 0.2537 | K36: 16 | L36: 54 | M36: 70
A37: 36 | B37: 40545 | C37: 12 | D37: FALSE | E37: =IF(WEEKDAY(B37,2)>=6,"Weekend","Weekday") -> Weekend | F37: 2 | G37: 0.36 | H37: 0.3333 | I37: 0.66 | J37: 0.2985 | K37: 20 | L37: 73 | M37: 93
A38: 37 | B38: 40545 | C38: 13 | D38: FALSE | E38: =IF(WEEKDAY(B38,2)>=6,"Weekend","Weekday") -> Weekend | F38: 2 | G38: 0.36 | H38: 0.3485 | I38: 0.66 | J38: 0.1343 | K38: 11 | L38: 64 | M38: 75
... A1001: 619 | B1001: 40572 | C1001: 0 | D1001: FALSE | E1001: =IF(WEEKDAY(B1001,2)>=6,"Weekend","Weekday") -> Weekend | F1001: 1 | G1001: 0.22 | H1001: 0.197 | I1001: 0.64 | J1001: 0.3582 | K1001: 2 | L1001: 26 | M1001: 28

Sheet PIVOT TABLE & CHARTS
D2: Pivot Tabel and Chart of Weather | N2: Pivot Tabel and Chart of Temperature | AC2: Pivot Tabel and Chart of Date
M5: Temperature | N5: Sum of Count | AA5: Date | AB5: Sum of Count
M6: 0.02 | N6: 63 | AA6: 01-Jan | AB6: 985
M7: 0.04 | N7: 208 | AA7: 02-Jan | AB7: 801
M8: 0.06 | N8: 287 | AA8: 08-Jan | AB8: 959
M9: 0.08 | N9: 235 | AA9: 09-Jan | AB9: 822
A10: Weather | B10: Sum of Count | M10: 0.1 | N10: 248 | AA10: 15-Jan | AB10: 1248
A11: 1 | B11: 11309 | M11: 0.12 | N11: 504 | AA11: 16-Jan | AB11: 1204
A12: 2 | B12: 3780 | M12: 0.14 | N12: 667 | AA12: 22-Jan | AB12: 981
A13: 3 | B13: 780 | M13: 0.16 | N13: 935 | AA13: 23-Jan | AB13: 986
A14: Grand Total | B14: 15869 | M14: 0.18 | N14: 910 | AA14: 29-Jan | AB14: 1098
M15: 0.2 | N15: 1044 | AA15: 30-Jan | AB15: 1096
M16: 0.22 | N16: 1517 | AA16: 05-Feb | AB16: 1005
M17: 0.24 | N17: 1020 | AA17: 06-Feb | AB17: 1623
M18: 0.26 | N18: 957 | AA18: 12-Feb | AB18: 1472
M19: 0.28 | N19: 762 | AA19: 13-Feb | AB19: 1589
M20: 0.3 | N20: 1410 | AA20: Grand Total | AB20: 15869
M21: 0.32 | N21: 794
M22: 0.34 | N22: 1759
D23: Pivot Tabel and Chart of Hour | M23: 0.36 | N23: 611
M24: 0.38 | N24: 210
M25: 0.4 | N25: 750
A26: Hour | B26: Sum of Count | M26: 0.42 | N26: 519
A27: 0-2 | B27: 928 | M27: 0.44 | N27: 194
A28: 3-5 | B28: 189 | M28: 0.46 | N28: 265
A29: 6-8 | B29: 353 | M29: Grand Total | N29: 15869
A30: 9-11 | B30: 2389
A31: 12-14 | B31: 4282
A32: 15-17 | B32: 4220
A33: 18-20 | B33: 2160
A34: 21-23 | B34: 1348 | N34: Pivot Tabel and Chart of Windspeed
A35: Grand Total | B35: 15869
M38: Windspeed | N38: Sum of Count
M39: 0 | N39: 1904
M40: 0.0896 | N40: 927
M41: 0.1045 | N41: 931
M42: 0.1343 | N42: 958
M43: 0.1642 | N43: 1245
M44: 0.194 | N44: 989
M45: 0.2239 | N45: 696
...

Sheet STATISTICAL SUMMARY
C1: BIKE SHARING DATA — INSIGHTS & STATISTICS
C3: Summary of customer demand, usage patterns and key statistical measures
C6: KEY PERFORMANCE INDICATORS
C7: Total Rentals | E7: Registered Customers | H7: Casual Customers | J7: Average Rentals | M7: Highest Demand | O7: Total Records
C8: =SUM('FINAL RESULT'!M2:M1001) -> 58304 | E8: =SUM('FINAL RESULT'!L2:L1001) -> 53383 | H8: =SUM('FINAL RESULT'!K2:K1001) -> 4921 | J8: =AVERAGE('FINAL RESULT'!M2:M1001) -> 58.304 | M8: =MAX('FINAL RESULT'!M2:M1001) -> 249 | O8: =COUNT('FINAL RESULT'!M2:M1001) -> 1000
C11: STATISTICAL SUMMARY | I11: REQUIRED STATISTICAL FUNCTIONS
C12: Variable | D12: Average | E12: Minimum | F12: Maximum | G12: Std. Deviation | I12: Function | K12: Purpose | N12: Result
C13: Casual | D13: =AVERAGE('FINAL RESULT'!K2:K1001) -> 4.921 | E13: =MIN('FINAL RESULT'!K2:K1001) -> 0 | F13: =MAX('FINAL RESULT'!K2:K1001) -> 62 | G13: =_xlfn.STDEV.S('FINAL RESULT'!M2:M1001) -> 50.985558 | I13: COUNTIF | K13: Count values above 100 | N13: =COUNTIF('FINAL RESULT'!M2:M1001,">100") -> 170
C14: Registered | D14: =AVERAGE('FINAL RESULT'!L2:L1001) -> 53.383 | E14: =MIN('FINAL RESULT'!L2:L1001) -> 0 | F14: =MAX('FINAL RESULT'!L2:L1001) -> 247 | G14: =_xlfn.STDEV.S('FINAL RESULT'!L2:L1001) -> 47.893968 | I14: SUMIF | K14: Sum of values above 100 | N14: =SUMIF('FINAL RESULT'!M2:M1001,">100",'FINAL RESULT'!M2:M1001) -> 25164
C15: Total Count | D15: =AVERAGE('FINAL RESULT'!M2:M1001) -> 58.304 | E15: =MIN('FINAL RESULT'!M2:M1001) -> 1 | F15: =MAX('FINAL RESULT'!M2:M1001) -> 249 | G15: =_xlfn.STDEV.S('FINAL RESULT'!M2:M1001) -> 50.985558 | I15: STDEV | K15: Standard deviation of demand | N15: =_xlfn.STDEV.S('FINAL RESULT'!M2:M1001) -> 50.985558
I16: CORREL | K16: Casual vs Registered relationship | N16: =CORREL('FINAL RESULT'!K2:K1001,'FINAL RESULT'!L2:L1001) -> 0.33770561
C18: DEMAND PATTERN
C19: Hour | D19: Sum of Count | F19: Weather | G19: Sum of Count | I19: Temperature | J19: Sum of Count | M19: Windspeed | N19: Sum of Count
C20: 0-2 | D20: 928 | F20: 1 | G20: 11309 | I20: 0.02 | J20: 63 | M20: 0 | N20: 1904
C21: 3-5 | D21: 189 | F21: 2 | G21: 3780 | I21: 0.04 | J21: 208 | M21: 0.0896 | N21: 927
C22: 6-8 | D22: 353 | F22: 3 | G22: 780 | I22: 0.06 | J22: 287 | M22: 0.1045 | N22: 931
C23: 9-11 | D23: 2389 | F23: Grand Total | G23: 15869 | I23: 0.08 | J23: 235 | M23: 0.1343 | N23: 958
C24: 12-14 | D24: 4282 | I24: 0.1 | J24: 248 | M24: 0.1642 | N24: 1245
C25: 15-17 | D25: 4220 | I25: 0.12 | J25: 504 | M25: 0.194 | N25: 989
C26: 18-20 | D26: 2160 | I26: 0.14 | J26: 667 | M26: 0.2239 | N26: 696
C27: 21-23 | D27: 1348 | I27: 0.16 | J27: 935 | M27: 0.2537 | N27: 1645
C28: Grand Total | D28: 15869 | I28: 0.18 | J28: 910 | M28: 0.2836 | N28: 1124
I29: 0.2 | J29: 1044 | M29: 0.2985 | N29: 1045
I30: 0.22 | J30: 1517 | M30: 0.3284 | N30: 976
I31: 0.24 | J31: 1020 | M31: 0.3582 | N31: 719
I32: 0.26 | J32: 957 | M32: 0.3881 | N32: 444
I33: 0.28 | J33: 762 | M33: 0.4179 | N33: 683
I34: 0.3 | J34: 1410 | M34: 0.4478 | N34: 731
I35: 0.32 | J35: 794 | M35: 0.4627 | N35: 483
I36: 0.34 | J36: 1759 | M36: 0.4925 | N36: 95
I37: 0.36 | J37: 611 | M37: 0.5224 | N37: 205
I38: 0.38 | J38: 210 | M38: 0.5522 | N38: 69
I39: 0.4 | J39: 750 | M39: Grand Total | N39: 15869
I40: 0.42 | J40: 519
I41: 0.44 | J41: 194
I42: 0.46 | J42: 265
I43: Grand Total | J43: 15869
C88: CUSTOMER DEMAND INSIGHTS
C89: Total Rentals | E89: Average Rentals | H89: Highest Demand | J89: Lowest Demand | M89: Demand > 100
C90: =SUM('FINAL RESULT'!M2:M1001) -> 58304 | E90: =AVERAGE('FINAL RESULT'!M2:M1001) -> 58.304 | H90: =MAX('FINAL RESULT'!M2:M1001) -> 249 | J90: =MIN('FINAL RESULT'!M2:M1001) -> 1 | M90: =COUNTIF('FINAL RESULT'!M2:M1001,">100") -> 170
...

Sheet DASHBOARD

Sheet FORECASTING
A1: Date | B1: Count | C1: Forecast(Count) | D1: Lower Confidence Bound(Count) | E1: Upper Confidence Bound(Count)
A2: 40544 | B2: 41.041667
A3: 40545 | B3: 34.826087
A4: 40546 | B4: 61.318182
A5: 40547 | B5: 67.913043
A6: 40548 | B6: 69.565217
A7: 40549 | B7: 69.826087
A8: 40550 | B8: 65.652174
A9: 40551 | B9: 39.958333
A10: 40552 | B10: 34.25
A11: 40553 | B11: 55.041667
A12: 40554 | B12: 57.409091
A13: 40555 | B13: 52.818182
... A45: 40587 | B45: 69.086957
A46: 40588 | B46: 18.875 | C46: 18.875 | D46: 18.875 | E46: 18.875
A47: 40589 | C47: =_xlfn.FORECAST.ETS(A47,$B$2:$B$46,$A$2:$A$46,1,1) -> 61.270134 | D47: =C47-_xlfn.FORECAST.ETS.CONFINT(A47,$B$2:$B$46,$A$2:$A$46,0.95,1,1) -> 31.858656 | E47: =C47+_xlfn.FORECAST.ETS.CONFINT(A47,$B$2:$B$46,$A$2:$A$46,0.95,1,1) -> 90.681612
A48: 40590 | C48: =_xlfn.FORECAST.ETS(A48,$B$2:$B$46,$A$2:$A$46,1,1) -> 61.525828 | D48: =C48-_xlfn.FORECAST.ETS.CONFINT(A48,$B$2:$B$46,$A$2:$A$46,0.95,1,1) -> 31.878109 | E48: =C48+_xlfn.FORECAST.ETS.CONFINT(A48,$B$2:$B$46,$A$2:$A$46,0.95,1,1) -> 91.173546
A49: 40591 | C49: =_xlfn.FORECAST.ETS(A49,$B$2:$B$46,$A$2:$A$46,1,1) -> 61.781521 | D49: =C49-_xlfn.FORECAST.ETS.CONFINT(A49,$B$2:$B$46,$A$2:$A$46,0.95,1,1) -> 31.89574 | E49: =C49+_xlfn.FORECAST.ETS.CONFINT(A49,$B$2:$B$46,$A$2:$A$46,0.95,1,1) -> 91.667303
A50: 40592 | C50: =_xlfn.FORECAST.ETS(A50,$B$2:$B$46,$A$2:$A$46,1,1) -> 62.037215 | D50: =C50-_xlfn.FORECAST.ETS.CONFINT(A50,$B$2:$B$46,$A$2:$A$46,0.95,1,1) -> 31.911562 | E50: =C50+_xlfn.FORECAST.ETS.CONFINT(A50,$B$2:$B$46,$A$2:$A$46,0.95,1,1) -> 92.162868
A51: 40593 | C51: =_xlfn.FORECAST.ETS(A51,$B$2:$B$46,$A$2:$A$46,1,1) -> 62.292909 | D51: =C51-_xlfn.FORECAST.ETS.CONFINT(A51,$B$2:$B$46,$A$2:$A$46,0.95,1,1) -> 31.925589 | E51: =C51+_xlfn.FORECAST.ETS.CONFINT(A51,$B$2:$B$46,$A$2:$A$46,0.95,1,1) -> 92.660228
A52: 40594 | C52: =_xlfn.FORECAST.ETS(A52,$B$2:$B$46,$A$2:$A$46,1,1) -> 62.548602 | D52: =C52-_xlfn.FORECAST.ETS.CONFINT(A52,$B$2:$B$46,$A$2:$A$46,0.95,1,1) -> 31.937837 | E52: =C52+_xlfn.FORECAST.ETS.CONFINT(A52,$B$2:$B$46,$A$2:$A$46,0.95,1,1) -> 93.159367
A53: 40595 | C53: =_xlfn.FORECAST.ETS(A53,$B$2:$B$46,$A$2:$A$46,1,1) -> 62.804296 | D53: =C53-_xlfn.FORECAST.ETS.CONFINT(A53,$B$2:$B$46,$A$2:$A$46,0.95,1,1) -> 31.948319 | E53: =C53+_xlfn.FORECAST.ETS.CONFINT(A53,$B$2:$B$46,$A$2:$A$46,0.95,1,1) -> 93.660273
A54: 40596 | C54: =_xlfn.FORECAST.ETS(A54,$B$2:$B$46,$A$2:$A$46,1,1) -> 63.05999 | D54: =C54-_xlfn.FORECAST.ETS.CONFINT(A54,$B$2:$B$46,$A$2:$A$46,0.95,1,1) -> 31.957049 | E54: =C54+_xlfn.FORECAST.ETS.CONFINT(A54,$B$2:$B$46,$A$2:$A$46,0.95,1,1) -> 94.16293
A55: 40597 | C55: =_xlfn.FORECAST.ETS(A55,$B$2:$B$46,$A$2:$A$46,1,1) -> 63.315683 | D55: =C55-_xlfn.FORECAST.ETS.CONFINT(A55,$B$2:$B$46,$A$2:$A$46,0.95,1,1) -> 31.964041 | E55: =C55+_xlfn.FORECAST.ETS.CONFINT(A55,$B$2:$B$46,$A$2:$A$46,0.95,1,1) -> 94.667326
A56: 40598 | C56: =_xlfn.FORECAST.ETS(A56,$B$2:$B$46,$A$2:$A$46,1,1) -> 63.571377 | D56: =C56-_xlfn.FORECAST.ETS.CONFINT(A56,$B$2:$B$46,$A$2:$A$46,0.95,1,1) -> 31.969308 | E56: =C56+_xlfn.FORECAST.ETS.CONFINT(A56,$B$2:$B$46,$A$2:$A$46,0.95,1,1) -> 95.173446
A57: 40599 | C57: =_xlfn.FORECAST.ETS(A57,$B$2:$B$46,$A$2:$A$46,1,1) -> 63.82707 | D57: =C57-_xlfn.FORECAST.ETS.CONFINT(A57,$B$2:$B$46,$A$2:$A$46,0.95,1,1) -> 31.972864 | E57: =C57+_xlfn.FORECAST.ETS.CONFINT(A57,$B$2:$B$46,$A$2:$A$46,0.95,1,1) -> 95.681276
A58: 40600 | C58: =_xlfn.FORECAST.ETS(A58,$B$2:$B$46,$A$2:$A$46,1,1) -> 64.082764 | D58: =C58-_xlfn.FORECAST.ETS.CONFINT(A58,$B$2:$B$46,$A$2:$A$46,0.95,1,1) -> 31.974723 | E58: =C58+_xlfn.FORECAST.ETS.CONFINT(A58,$B$2:$B$46,$A$2:$A$46,0.95,1,1) -> 96.190805

Sheet ANOMALY DETECTION
A1: Date | B1: Count | C1: Z-Score | D1: Anomaly Status | F1: Status | G1: Count
A2: ='FINAL RESULT'!B2 -> 40544 | B2: ='FINAL RESULT'!M2 -> 16 | C2: =(B2-AVERAGE($B$2:$B$1001))/_xlfn.STDEV.S($B$2:$B$1001) -> -0.82972516 | D2: =IF(ABS(C2)>=2,"Anomaly","Normal") -> Normal | F2: Anomaly | G2: =COUNTIF(D2:D1001,"Anomaly") -> 0
A3: ='FINAL RESULT'!B3 -> 40544 | B3: ='FINAL RESULT'!M3 -> 40 | F3: Normal | G3: =COUNTIF(D2:D1001,"Normal") -> 1
A4: ='FINAL RESULT'!B4 -> 40544 | B4: ='FINAL RESULT'!M4 -> 32
A5: ='FINAL RESULT'!B5 -> 40544 | B5: ='FINAL RESULT'!M5 -> 13
A6: ='FINAL RESULT'!B6 -> 40544 | B6: ='FINAL RESULT'!M6 -> 1
A7: ='FINAL RESULT'!B7 -> 40544 | B7: ='FINAL RESULT'!M7 -> 1
A8: ='FINAL RESULT'!B8 -> 40544 | B8: ='FINAL RESULT'!M8 -> 2
A9: ='FINAL RESULT'!B9 -> 40544 | B9: ='FINAL RESULT'!M9 -> 3
A10: ='FINAL RESULT'!B10 -> 40544 | B10: ='FINAL RESULT'!M10 -> 8
A11: ='FINAL RESULT'!B11 -> 40544 | B11: ='FINAL RESULT'!M11 -> 14
A12: ='FINAL RESULT'!B12 -> 40544 | B12: ='FINAL RESULT'!M12 -> 36
A13: ='FINAL RESULT'!B13 -> 40544 | B13: ='FINAL RESULT'!M13 -> 56
A14: ='FINAL RESULT'!B14 -> 40544 | B14: ='FINAL RESULT'!M14 -> 84
A15: ='FINAL RESULT'!B15 -> 40544 | B15: ='FINAL RESULT'!M15 -> 94
... A1001: ='FINAL RESULT'!B1001 -> 40572 | B1001: ='FINAL RESULT'!M1001 -> 28
